Youbot dynamics: running in arm-only mode
INFO: created undeclared connector root.initial
rfsm_timeevent: time-event extension loaded
Please run "youbot_test_help()" for information on available functions
Configuring dynamics
[0m[ INFO] [1336143944.573455867]: Joint 'base_x_joint' is of type PRISMATIC without limits[0m
[0m[ INFO] [1336143944.573781888]: Joint 'base_y_joint' is of type PRISMATIC without limits[0m
[33m[ WARN] [1336143944.577505989]: The root link base_footprint has an inertia specified in the URDF, but KDL does not support a root link with an inertia.  As a workaround, you can add an extra dummy link to your URDF.[0m
[35mTaskContext[0m: [1m[32mdyn[0m[0m
[35mstate[0m: [31mStopped[0m
[35misActive[0m: true
[35mgetPeriod[0m: 1
[35mpeers[0m: reporter
[35mports[0m: 
   [37mJointState[0m [[1m[36min[0m[0m, /sensor_msgs/JointState, [32mconn[0m, local] [31m// [0m
   [37mEEWrench[0m [[1m[36min[0m[0m, /geometry_msgs/Wrench, [33munconn[0m, local] [31m// [0m
   [37mJointAccelerations[0m [[1m[36min[0m[0m, /motion_control_msgs/JointAccelerations, [33munconn[0m, local] [31m// [0m
   [37mJointEfforts[0m [[1m[35mout[0m[0m, /motion_control_msgs/JointEfforts, [32mconn[0m, local] [31m// [0m
   [37mBaseTwist[0m [[1m[35mout[0m[0m, /geometry_msgs/Twist, [33munconn[0m, local] [31m// [0m
[35mproperties[0m:
   [37mrobot_description[0m (string) = 
		[33m<?xml version="1.0" ?>
		<!-- =================================================================================== -->
		<!-- |    This document was autogenerated by xacro from /home/youbot/ros_stacks/youbot-ros-pkg/youbot_common/youbot_description/robots/youbot.urdf.xacro | -->
		<!-- |    EDITING THIS FILE BY HAND IS NOT RECOMMENDED                                 | -->
		<!-- =================================================================================== -->
		<robot name="youbot" xmlns:controller="http://playerstage.sourceforge.net/gazebo/xmlschema/#controller" xmlns:interface="http://playerstage.sourceforge.net/gazebo/xmlschema/#interface" xmlns:sensor="http://playerstage.sourceforge.net/gazebo/xmlschema/#sensor" xmlns:xacro="http://ros.org/wiki/xacro">
		  <!-- The following included files set up definitions of parts of the robot body -->
		  <!-- misc common stuff? -->
		  <!-- youbot base -->
		  <!-- youbot plate -->
		  <!-- youbot arm -->
		  <!-- youbot gripper -->
		  <!-- generic simulator_gazebo plugins for starting mechanism control, ros time, ros battery -->
		  <gazebo>
		    <controller:gazebo_ros_controller_manager name="gazebo_ros_controller_manager" plugin="libgazebo_ros_controller_manager.so">
		      <alwaysOn>true</alwaysOn>
		      <updateRate>1000.0</updateRate>
		      <interface:audio name="gazebo_ros_controller_manager_dummy_iface"/>
		    </controller:gazebo_ros_controller_manager>
		    <controller:gazebo_ros_power_monitor name="gazebo_ros_power_monitor_controller" plugin="libgazebo_ros_power_monitor.so">
		      <alwaysOn>true</alwaysOn>
		      <updateRate>1.0</updateRate>
		      <timeout>5</timeout>
		      <interface:audio name="power_monitor_dummy_interface"/>
		      <powerStateTopic>power_state</powerStateTopic>
		      <powerStateRate>10.0</powerStateRate>
		      <fullChargeCapacity>87.78</fullChargeCapacity>
		      <dischargeRate>-474</dischargeRate>
		      <chargeRate>525</chargeRate>
		      <dischargeVoltage>15.52</dischargeVoltage>
		      <chargeVoltage>16.41</chargeVoltage>
		    </controller:gazebo_ros_power_monitor>
		  </gazebo>
		  <!-- materials for visualization -->
		  <material name="Orange">
		    <color rgba="1.0 0.4 0.0 1.0"/>
		  </material>
		  <material name="Grey">
		    <color rgba="0.7 0.7 0.7 1.0"/>
		  </material>
		  <material name="DarkGrey">
		    <color rgba="0.3 0.3 0.3 1.0"/>
		  </material>
		  <material name="White">
		    <color rgba="1.0 1.0 1.0 1.0"/>
		  </material>
		  <material name="Black">
		    <color rgba="0.0 0.0 0.0 1.0"/>
		  </material>
		  <material name="Red">
		    <color rgba="1.0 0.0 0.0 1.0"/>
		  </material>
		  <material name="Green">
		    <color rgba="0.0 1.0 0.0 1.0"/>
		  </material>
		  <!-- Now we can start using the macros included above to define the actual youbot -->
		  <!-- The first use of a macro.  This one was defined in base.urdf.xacro above.
		       A macro like this will expand to a set of link and joint definitions, and to additional
		       Gazebo-related extensions (sensor plugins, etc).  The macro takes an argument, name, 
		       that equals "base", and uses it to generate names for its component links and joints 
		       (e.g., base_link).  The included origin block is also an argument to the macro.  By convention, 
		       the origin block defines where the component is w.r.t its parent (in this case the parent 
		       is the world frame). For more, see http://www.ros.org/wiki/xacro -->
		  <!-- foot for arm-->
		  <link name="base_footprint">
		    <inertial>
		      <mass value="0.1"/>
		      <origin rpy="0 0 0" xyz="0 0 -0.05"/>
		      <inertia ixx="1.0" ixy="0.0" ixz="0.0" iyy="1.0" iyz="0.0" izz="1.0"/>
		    </inertial>
		    <visual>
		      <origin rpy="0 0 0" xyz="0 0 0"/>
		      <geometry>
		        <box size="0.001 0.001 0.001"/>
		      </geometry>
		      <material name="Red"/>
		    </visual>
		    <collision>
		      <origin rpy="0 0 0" xyz="0 0 -0.05"/>
		      <geometry>
		        <box size="0.001 0.001 0.001"/>
		      </geometry>
		    </collision>
		  </link>
		  <joint name="base_footprint_joint" type="fixed">
		    <origin rpy="0 0 0" xyz="0 0 0"/>
		    <child link="base_link"/>
		    <parent link="base_footprint"/>
		  </joint>
		  <link name="base_link">
		    <inertial>
		      <mass value="22.0"/>
		      <origin xyz="0 0 0"/>
		      <inertia ixx="5.652232699207" ixy="-0.009719934438" ixz="1.293988226423" iyy="5.669473158652" iyz="-0.007379583694" izz="3.683196351726"/>
		    </inertial>
		    <visual>
		      <origin rpy="0 0 0" xyz="0 0 0"/>
		      <geometry>
		        <mesh filename="package://youbot_description/meshes/youbot_base/base.dae"/>
		      </geometry>
		      <material name="DarkGrey"/>
		    </visual>
		    <collision>
		      <origin rpy="0 0 0" xyz="0 0 0"/>
		      <geometry>
		        <!--<box size="${base_size_x} ${base_size_y} ${base_size_z}" />-->
		        <mesh filename="package://youbot_description/meshes/youbot_base/base_convex.stl"/>
		      </geometry>
		    </collision>
		  </link>
		  <joint name="base_rot_joint" type="revolute">
		    <origin rpy="0 0 0" xyz="0 0 0"/>
		    <parent link="base_link"/>
		    <child link="base_x_link"/>
		    <axis xyz="0 0 1"/>
		    <!--<calibration rising="${arm_1_ref}" falling="${arm_1_ref}"/>-->
		    <!-- <dynamics damping="1.0" friction="1.0" /> -->
		    <limit effort="10" velocity="1.57079632679"/>
		    <!-- <safety_controller k_position="20" k_velocity="25" soft_lower_limit="${threshold}" soft_upper_limit="${joint_1_limit_soft}" /> -->
		  </joint>
		  <link name="base_x_link">
		    <inertial>
		      <mass value="0.01"/>
		      <origin xyz="0 0 0"/>
		      <inertia ixx="1" ixy="0" ixz="0" iyy="1" iyz="0" izz="1"/>
		    </inertial>
		  </link>
		  <joint name="base_x_joint" type="prismatic">
		    <origin rpy="0 0 0" xyz="0 0 0"/>
		    <parent link="base_x_link"/>
		    <child link="base_y_link"/>
		    <axis xyz="1 0 0"/>
		    <!--<calibration rising="${arm_1_ref}" falling="${arm_1_ref}"/>-->
		    <!-- <dynamics damping="1.0" friction="1.0" /> -->
		    <!-- <limit effort="10" velocity="${M_PI / 2.0}" lower="0" upper="${joint_1_limit}"/> -->
		    <!-- <safety_controller k_position="20" k_velocity="25" soft_lower_limit="${threshold}" soft_upper_limit="${joint_1_limit_soft}" /> -->
		  </joint>
		  <link name="base_y_link">
		    <inertial>
		      <mass value="0.01"/>
		      <origin xyz="0 0 0"/>
		      <inertia ixx="1" ixy="0" ixz="0" iyy="1" iyz="0" izz="1"/>
		    </inertial>
		  </link>
		  <joint name="base_y_joint" type="prismatic">
		    <origin rpy="0 0 0" xyz="0 0 0"/>
		    <parent link="base_y_link"/>
		    <child link="base_to_arm_link"/>
		    <axis xyz="0 1 0"/>
		    <!--<calibration rising="${arm_1_ref}" falling="${arm_1_ref}"/>-->
		    <!-- <dynamics damping="1.0" friction="1.0" /> -->
		    <!-- <limit effort="10" velocity="${M_PI / 2.0}" lower="0" upper="${joint_1_limit}"/> -->
		    <!-- <safety_controller k_position="20" k_velocity="25" soft_lower_limit="${threshold}" soft_upper_limit="${joint_1_limit_soft}" /> -->
		  </joint>
		  <link name="base_to_arm_link">
		    <inertial>
		      <mass value="0.01"/>
		      <origin xyz="0 0 0"/>
		      <inertia ixx="1" ixy="0" ixz="0" iyy="1" iyz="0" izz="1"/>
		    </inertial>
		  </link>
		  <joint name="base_laser_front_hokuyo_urg04_laser_joint" type="fixed">
		    <axis xyz="0 1 0"/>
		    <origin rpy="0 0 0" xyz="0.3 0 -0.03"/>
		    <parent link="base_link"/>
		    <child link="base_laser_front_link"/>
		  </joint>
		  <link name="base_laser_front_link" type="laser">
		    <inertial>
		      <mass value="0.16"/>
		      <origin rpy="0 0 0" xyz="0 0 0"/>
		      <inertia ixx="0.1" ixy="0" ixz="0" iyy="0.1" iyz="0" izz="0.1"/>
		    </inertial>
		    <visual>
		      <origin rpy="0 0 0" xyz="0 0 0"/>
		      <geometry>
		        <mesh filename="package://youbot_description/meshes/sensors/hokuyo.dae"/>
		      </geometry>
		      <material name="DarkGrey"/>
		    </visual>
		    <collision>
		      <origin rpy="0 0 0" xyz="0 0 0"/>
		      <geometry>
		        <mesh filename="package://youbot_description/meshes/sensors/hokuyo_convex.stl"/>
		      </geometry>
		    </collision>
		  </link>
		  <gazebo reference="base_laser_front_link">
		    <sensor:ray name="base_laser_front">
		      <rayCount>640</rayCount>
		      <rangeCount>640</rangeCount>
		      <laserCount>1</laserCount>
		      <origin>0.0 0.0 0.0</origin>
		      <displayRays>false</displayRays>
		      <minAngle>-119.748179182</minAngle>
		      <maxAngle>119.748179182</maxAngle>
		      <minRange>0.05</minRange>
		      <maxRange>5.6</maxRange>
		      <resRange>0.36</resRange>
		      <updateRate>10</updateRate>
		      <controller:gazebo_ros_laser name="gazebo_ros_base_laser_front_controller" plugin="libgazebo_ros_laser.so">
		        <gaussianNoise>0.005</gaussianNoise>
		        <alwaysOn>true</alwaysOn>
		        <updateRate>10</updateRate>
		        <topicName>scan_front</topicName>
		        <frameName>/base_laser_front_link</frameName>
		        <interface:laser name="gazebo_ros_base_laser_front_iface"/>
		      </controller:gazebo_ros_laser>
		    </sensor:ray>
		  </gazebo>
		  <joint name="caster_joint_fl" type="fixed">
		    <origin rpy="0 0 0" xyz="0.228 0.158 -0.034"/>
		    <axis xyz="0 0 1"/>
		    <limit effort="30" velocity="10"/>
		    <dynamics damping="1.0" friction="1.0"/>
		    <safety_controller k_velocity="10.0"/>
		    <parent link="base_link"/>
		    <child link="caster_link_fl"/>
		  </joint>
		  <link name="caster_link_fl">
		    <inertial>
		      <mass value="0.1"/>
		      <origin xyz="0 0 0"/>
		      <inertia ixx="0.012411765597" ixy="-0.000711733678" ixz="0.00050272983" iyy="0.015218160428" iyz="-0.000004273467" izz="0.011763977943"/>
		    </inertial>
		  </link>
		  <joint name="wheel_joint_fl" type="fixed">
		    <axis xyz="0 1 0"/>
		    <limit effort="30" velocity="10"/>
		    <origin rpy="0 0 0" xyz="0.0 0.0 0.0"/>
		    <parent link="caster_link_fl"/>
		    <dynamics damping="1.0" friction="1.0"/>
		    <safety_controller k_velocity="10.0"/>
		    <child link="wheel_link_fl"/>
		  </joint>
		  <link name="wheel_link_fl">
		    <inertial>
		      <mass value="0.4"/>
		      <origin xyz="0 0 0"/>
		      <inertia ixx="0.012411765597" ixy="-0.000711733678" ixz="0.00050272983" iyy="0.015218160428" iyz="-0.000004273467" izz="0.011763977943"/>
		    </inertial>
		    <visual>
		      <origin rpy="0 0 0" xyz="0 0 0"/>
		      <!--<mesh filename="package://youbot_description/meshes/youbot_base/youbot_wheel.stl" />-->
		      <geometry>
		        <sphere radius="0.05"/>
		      </geometry>
		      <material name="Orange"/>
		    </visual>
		    <collision>
		      <origin rpy="1.57079632679 0 0" xyz="0 0 0"/>
		      <geometry>
		        <cylinder length="0.005" radius="0.05"/>
		      </geometry>
		    </collision>
		  </link>
		  <joint name="caster_joint_fr" type="fixed">
		    <origin rpy="0 0 0" xyz="0.228 -0.158 -0.034"/>
		    <axis xyz="0 0 1"/>
		    <limit effort="30" velocity="10"/>
		    <dynamics damping="1.0" friction="1.0"/>
		    <safety_controller k_velocity="10.0"/>
		    <parent link="base_link"/>
		    <child link="caster_link_fr"/>
		  </joint>
		  <link name="caster_link_fr">
		    <inertial>
		      <mass value="0.1"/>
		      <origin xyz="0 0 0"/>
		      <inertia ixx="0.012411765597" ixy="-0.000711733678" ixz="0.00050272983" iyy="0.015218160428" iyz="-0.000004273467" izz="0.011763977943"/>
		    </inertial>
		  </link>
		  <joint name="wheel_joint_fr" type="fixed">
		    <axis xyz="0 1 0"/>
		    <limit effort="30" velocity="10"/>
		    <dynamics damping="1.0" friction="1.0"/>
		    <safety_controller k_velocity="10.0"/>
		    <origin rpy="0 0 0" xyz="0.0 0.0 0.0"/>
		    <parent link="caster_link_fr"/>
		    <child link="wheel_link_fr"/>
		  </joint>
		  <link name="wheel_link_fr">
		    <inertial>
		      <mass value="0.4"/>
		      <origin xyz="0 0 0"/>
		      <inertia ixx="0.012411765597" ixy="-0.000711733678" ixz="0.00050272983" iyy="0.015218160428" iyz="-0.000004273467" izz="0.011763977943"/>
		    </inertial>
		    <visual>
		      <origin rpy="0 0 0" xyz="0 0 0"/>
		      <geometry>
		        <!--<mesh filename="package://youbot_description/meshes/youbot_base/youbot_wheel.stl" />-->
		        <sphere radius="0.05"/>
		      </geometry>
		      <material name="Orange"/>
		    </visual>
		    <collision>
		      <origin rpy="1.57079632679 0 0" xyz="0 0 0"/>
		      <geometry>
		        <cylinder length="0.005" radius="0.05"/>
		      </geometry>
		    </collision>
		  </link>
		  <joint name="caster_joint_bl" type="fixed">
		    <origin rpy="0 0 0" xyz="-0.228 0.158 -0.034"/>
		    <axis xyz="0 0 1"/>
		    <limit effort="30" velocity="10"/>
		    <dynamics damping="1.0" friction="1.0"/>
		    <safety_controller k_velocity="10.0"/>
		    <parent link="base_link"/>
		    <child link="caster_link_bl"/>
		  </joint>
		  <link name="caster_link_bl">
		    <inertial>
		      <mass value="0.1"/>
		      <origin xyz="0 0 0"/>
		      <inertia ixx="0.012411765597" ixy="-0.000711733678" ixz="0.00050272983" iyy="0.015218160428" iyz="-0.000004273467" izz="0.011763977943"/>
		    </inertial>
		  </link>
		  <joint name="wheel_joint_bl" type="fixed">
		    <axis xyz="0 1 0"/>
		    <limit effort="10" velocity="10"/>
		    <limit effort="30" velocity="10"/>
		    <dynamics damping="1.0" friction="1.0"/>
		    <safety_controller k_velocity="10.0"/>
		    <origin rpy="0 0 0" xyz="0.0 0.0 0.0"/>
		    <parent link="caster_link_bl"/>
		    <child link="wheel_link_bl"/>
		  </joint>
		  <link name="wheel_link_bl">
		    <inertial>
		      <mass value="0.4"/>
		      <origin xyz="0 0 0"/>
		      <inertia ixx="0.012411765597" ixy="-0.000711733678" ixz="0.00050272983" iyy="0.015218160428" iyz="-0.000004273467" izz="0.011763977943"/>
		    </inertial>
		    <visual>
		      <origin rpy="0 0 0" xyz="0 0 0"/>
		      <geometry>
		        <!--<mesh filename="package://youbot_description/meshes/youbot_base/youbot_wheel.stl" />-->
		        <sphere radius="0.05"/>
		      </geometry>
		      <material name="Orange"/>
		    </visual>
		    <collision>
		      <origin rpy="1.57079632679 0 0" xyz="0 0 0"/>
		      <geometry>
		        <cylinder length="0.005" radius="0.05"/>
		      </geometry>
		    </collision>
		  </link>
		  <joint name="caster_joint_br" type="fixed">
		    <origin rpy="0 0 0" xyz="-0.228 -0.158 -0.034"/>
		    <axis xyz="0 0 1"/>
		    <limit effort="30" velocity="10"/>
		    <dynamics damping="1.0" friction="1.0"/>
		    <safety_controller k_velocity="10.0"/>
		    <parent link="base_link"/>
		    <child link="caster_link_br"/>
		  </joint>
		  <link name="caster_link_br">
		    <inertial>
		      <mass value="0.1"/>
		      <origin xyz="0 0 0"/>
		      <inertia ixx="0.012411765597" ixy="-0.000711733678" ixz="0.00050272983" iyy="0.015218160428" iyz="-0.000004273467" izz="0.011763977943"/>
		    </inertial>
		  </link>
		  <joint name="wheel_joint_br" type="fixed">
		    <axis xyz="0 1 0"/>
		    <limit effort="30" velocity="10"/>
		    <dynamics damping="1.0" friction="1.0"/>
		    <safety_controller k_velocity="10.0"/>
		    <origin rpy="0 0 0" xyz="0.0 0.0 0.0"/>
		    <parent link="caster_link_br"/>
		    <child link="wheel_link_br"/>
		  </joint>
		  <link name="wheel_link_br">
		    <inertial>
		      <mass value="0.4"/>
		      <origin xyz="0 0 0"/>
		      <inertia ixx="0.012411765597" ixy="-0.000711733678" ixz="0.00050272983" iyy="0.015218160428" iyz="-0.000004273467" izz="0.011763977943"/>
		    </inertial>
		    <visual>
		      <origin rpy="0 0 0" xyz="0 0 0"/>
		      <geometry>
		        <!--<mesh filename="package://youbot_description/meshes/youbot_base/youbot_wheel.stl" />-->
		        <sphere radius="0.05"/>
		      </geometry>
		      <material name="Orange"/>
		    </visual>
		    <collision>
		      <origin rpy="1.57079632679 0 0" xyz="0 0 0"/>
		      <geometry>
		        <cylinder length="0.005" radius="0.05"/>
		      </geometry>
		    </collision>
		  </link>
		  <gazebo reference="youbot_base">
		    <material value="youbot/DarkGrey"/>
		  </gazebo>
		  <gazebo reference="wheel_link_fl">
		    <material value="youbot/Orange"/>
		  </gazebo>
		  <gazebo reference="caster_link_fl">
		    <material value="youbot/Orange"/>
		  </gazebo>
		  <gazebo reference="wheel_link_fr">
		    <material value="youbot/Orange"/>
		  </gazebo>
		  <gazebo reference="caster_link_fr">
		    <material value="youbot/Orange"/>
		  </gazebo>
		  <gazebo reference="wheel_link_bl">
		    <material value="youbot/Orange"/>
		  </gazebo>
		  <gazebo reference="caster_link_bl">
		    <material value="youbot/Orange"/>
		  </gazebo>
		  <gazebo reference="wheel_link_br">
		    <material value="youbot/Orange"/>
		  </gazebo>
		  <gazebo reference="caster_link_br">
		    <material value="youbot/Orange"/>
		  </gazebo>
		  <gazebo>
		    <controller:gazebo_ros_p3d name="p3d_base_controller" plugin="libgazebo_ros_p3d.so">
		      <alwaysOn>true</alwaysOn>
		      <updateRate>100.0</updateRate>
		      <bodyName>base_link</bodyName>
		      <topicName>base_pose_ground_truth</topicName>
		      <gaussianNoise>0.01</gaussianNoise>
		      <frameName>map</frameName>
		      <xyzOffsets>25.7 25.7 0</xyzOffsets>
		      <!-- initialize odometry for fake localization-->
		      <rpyOffsets>0 0 0</rpyOffsets>
		      <interface:position name="p3d_base_position"/>
		    </controller:gazebo_ros_p3d>
		    <canonicalBody>base_footprint</canonicalBody>
		  </gazebo>
		  <transmission name="wheel_trans_fl" type="pr2_mechanism_model/SimpleTransmission">
		    <actuator name="wheel_motor_fl"/>
		    <joint name="wheel_joint_fl"/>
		    <mechanicalReduction>79.2380952381</mechanicalReduction>
		  </transmission>
		  <transmission name="caster_trans_fl" type="pr2_mechanism_model/SimpleTransmission">
		    <actuator name="caster_motor_fl"/>
		    <joint name="caster_joint_fl"/>
		    <mechanicalReduction>79.2380952381</mechanicalReduction>
		  </transmission>
		  <transmission name="wheel_trans_fr" type="pr2_mechanism_model/SimpleTransmission">
		    <actuator name="wheel_motor_fr"/>
		    <joint name="wheel_joint_fr"/>
		    <mechanicalReduction>79.2380952381</mechanicalReduction>
		  </transmission>
		  <transmission name="caster_trans_fr" type="pr2_mechanism_model/SimpleTransmission">
		    <actuator name="caster_motor_fr"/>
		    <joint name="caster_joint_fr"/>
		    <mechanicalReduction>79.2380952381</mechanicalReduction>
		  </transmission>
		  <transmission name="wheel_trans_bl" type="pr2_mechanism_model/SimpleTransmission">
		    <actuator name="wheel_motor_bl"/>
		    <joint name="wheel_joint_bl"/>
		    <mechanicalReduction>79.2380952381</mechanicalReduction>
		  </transmission>
		  <transmission name="caster_trans_bl" type="pr2_mechanism_model/SimpleTransmission">
		    <actuator name="caster_motor_bl"/>
		    <joint name="caster_joint_bl"/>
		    <mechanicalReduction>79.2380952381</mechanicalReduction>
		  </transmission>
		  <transmission name="wheel_trans_br" type="pr2_mechanism_model/SimpleTransmission">
		    <actuator name="wheel_motor_br"/>
		    <joint name="wheel_joint_br"/>
		    <mechanicalReduction>79.2380952381</mechanicalReduction>
		  </transmission>
		  <transmission name="caster_trans_br" type="pr2_mechanism_model/SimpleTransmission">
		    <actuator name="caster_motor_br"/>
		    <joint name="caster_joint_br"/>
		    <mechanicalReduction>79.2380952381</mechanicalReduction>
		  </transmission>
		  <joint name="plate_joint" type="fixed">
		    <origin rpy="0 0 0" xyz="-0.159 0 0.046"/>
		    <parent link="base_link"/>
		    <child link="plate_link"/>
		  </joint>
		  <link name="plate_link">
		    <inertial>
		      <origin rpy="0 0 0" xyz="0 0 0"/>
		      <mass value="1"/>
		      <inertia ixx="0.01" ixy="0" ixz="0" iyy="0.01" iyz="0" izz="0.01"/>
		    </inertial>
		    <visual>
		      <origin rpy="0 0 0" xyz="0 0 0"/>
		      <geometry>
		        <mesh filename="package://youbot_description/meshes/youbot_plate/plate.dae"/>
		      </geometry>
		      <material name="DarkGrey"/>
		    </visual>
		    <collision>
		      <origin rpy="0 0 0" xyz="0 0 0"/>
		      <geometry>
		        <mesh filename="package://youbot_description/meshes/youbot_plate/plate_convex.stl"/>
		      </geometry>
		    </collision>
		  </link>
		  <joint name="arm_joint_0" type="fixed">
		    <origin rpy="0 0 0" xyz="0.143 0 0.046"/>
		    <parent link="base_to_arm_link"/>
		    <child link="arm_link_0"/>
		  </joint>
		  <link name="arm_link_0">
		    <inertial>
		      <!--<origin xyz="0.023 0 0.006" rpy="0 0 0"/>-->
		      <origin rpy="0 0 0" xyz="0 0 0"/>
		      <mass value="0.845"/>
		      <inertia ixx="0.01" ixy="0" ixz="0" iyy="0.01" iyz="0" izz="0.01"/>
		    </inertial>
		    <visual>
		      <origin rpy="0 0 0" xyz="0 0 0"/>
		      <geometry>
		        <mesh filename="package://youbot_description/meshes/youbot_arm/arm0.dae"/>
		      </geometry>
		      <material name="DarkGrey"/>
		    </visual>
		    <collision>
		      <!--<origin xyz="0.023 0 0.006" rpy="0 0 0"/>-->
		      <origin rpy="0 0 0" xyz="0 0 0"/>
		      <geometry>
		        <mesh filename="package://youbot_description/meshes/youbot_arm/arm0_convex.stl"/>
		        <!--<cylinder length="0.078" radius="0.093"/>-->
		      </geometry>
		    </collision>
		  </link>
		  <joint name="arm_joint_1" type="revolute">
		    <origin rpy="0 0 0" xyz="0.024 0 0.096"/>
		    <parent link="arm_link_0"/>
		    <child link="arm_link_1"/>
		    <axis xyz="0 0 1"/>
		    <!--<calibration rising="${arm_1_ref}" falling="${arm_1_ref}"/>-->
		    <dynamics damping="1.0" friction="1.0"/>
		    <limit effort="10" lower="0" upper="5.89921287174" velocity="1.57079632679"/>
		    <safety_controller k_position="20" k_velocity="25" soft_lower_limit="0.001" soft_upper_limit="5.89821287174"/>
		  </joint>
		  <link name="arm_link_1">
		    <inertial>
		      <!--<origin xyz="0 0 -0.003" rpy="0 0 0" />-->
		      <origin rpy="0 0 0" xyz="0 0 0"/>
		      <mass value="2.412"/>
		      <inertia ixx="0.01" ixy="0" ixz="0" iyy="0.01" iyz="0" izz="0.01"/>
		    </inertial>
		    <visual>
		      <origin rpy="0 0 0" xyz="0 0 0"/>
		      <geometry>
		        <mesh filename="package://youbot_description/meshes/youbot_arm/arm1.dae"/>
		      </geometry>
		      <!--<material name="Orange" />-->
		    </visual>
		    <collision>
		      <!--<origin xyz="0 0 -0.003" rpy="0 0 0" />-->
		      <origin rpy="0 0 0" xyz="0 0 0"/>
		      <geometry>
		        <mesh filename="package://youbot_description/meshes/youbot_arm/arm1_convex.stl"/>
		        <!--<cylinder length="0.102" radius="0.080"/>-->
		      </geometry>
		    </collision>
		  </link>
		  <joint name="arm_joint_2" type="revolute">
		    <origin rpy="0 0 0" xyz="0.033 0 0.019"/>
		    <parent link="arm_link_1"/>
		    <child link="arm_link_2"/>
		    <axis xyz="0 -1 0"/>
		    <!--<calibration rising="${arm_2_ref}" falling="${arm_2_ref}"/>-->
		    <dynamics damping="1.0" friction="1.0"/>
		    <limit effort="10" lower="0" upper="2.70526034059" velocity="1.57079632679"/>
		    <safety_controller k_position="20" k_velocity="25" soft_lower_limit="0.001" soft_upper_limit="2.70426034059"/>
		  </joint>
		  <link name="arm_link_2">
		    <inertial>
		      <!--<origin xyz="0.001 -0.041 0.074" rpy="0 0 0" />-->
		      <origin rpy="0 0 0" xyz="0 -0.032 0.078"/>
		      <mass value="1.155"/>
		      <inertia ixx="0.01" ixy="0" ixz="0" iyy="0.01" iyz="0" izz="0.01"/>
		    </inertial>
		    <visual>
		      <origin rpy="0 0 0" xyz="0 -0.032 0.078"/>
		      <geometry>
		        <mesh filename="package://youbot_description/meshes/youbot_arm/arm2.dae"/>
		      </geometry>
		      <material name="Orange"/>
		    </visual>
		    <collision>
		      <!--<origin xyz="0.001 -0.041 0.074" rpy="0 0 0" />-->
		      <origin rpy="0 0 0" xyz="0 -0.032 0.078"/>
		      <geometry>
		        <mesh filename="package://youbot_description/meshes/youbot_arm/arm2_convex.stl"/>
		        <!--<box size="0.074 0.082 0.222"/>-->
		      </geometry>
		    </collision>
		  </link>
		  <joint name="arm_joint_3" type="revolute">
		    <origin rpy="0 0 0" xyz="0.000 0.000 0.155"/>
		    <parent link="arm_link_2"/>
		    <child link="arm_link_3"/>
		    <axis xyz="0 1 0"/>
		    <!--<calibration rising="${arm_3_ref}" falling="${arm_3_ref}"/>-->
		    <dynamics damping="1.0" friction="1.0"/>
		    <limit effort="10" lower="-5.18362787842" upper="0" velocity="1.57079632679"/>
		    <safety_controller k_position="20" k_velocity="25" soft_lower_limit="-5.18262787842" soft_upper_limit="0.001"/>
		  </joint>
		  <link name="arm_link_3">
		    <inertial>
		      <!--<origin xyz="0.000 0.025 0.067" rpy="0 0 0" />-->
		      <origin rpy="0 0 0" xyz="0.000 0.028 0.079"/>
		      <mass value="0.934"/>
		      <inertia ixx="0.01" ixy="0" ixz="0" iyy="0.01" iyz="0" izz="0.01"/>
		    </inertial>
		    <visual>
		      <origin rpy="0 0 0" xyz="0.000 0.028 0.079"/>
		      <geometry>
		        <mesh filename="package://youbot_description/meshes/youbot_arm/arm3.dae"/>
		      </geometry>
		      <material name="Orange"/>
		    </visual>
		    <collision>
		      <!--<origin xyz="0.000 0.025 0.067" rpy="0 0 0" />-->
		      <origin rpy="0 0 0" xyz="0.000 0.028 0.079"/>
		      <geometry>
		        <mesh filename="package://youbot_description/meshes/youbot_arm/arm3_convex.stl"/>
		        <!--<box size="0.064 0.054 0.192"/>-->
		      </geometry>
		    </collision>
		  </link>
		  <joint name="arm_joint_4" type="revolute">
		    <origin rpy="0 0 0" xyz="0.000 0.000 0.135"/>
		    <parent link="arm_link_3"/>
		    <child link="arm_link_4"/>
		    <axis xyz="0 -1 0"/>
		    <!--<calibration rising="${arm_4_ref}" falling="${arm_4_ref}"/>-->
		    <dynamics damping="1.0" friction="1.0"/>
		    <limit effort="10" lower="0" upper="3.57792496659" velocity="1.57079632679"/>
		    <safety_controller k_position="20" k_velocity="25" soft_lower_limit="0" soft_upper_limit="3.57692496659"/>
		  </joint>
		  <link name="arm_link_4">
		    <inertial>
		      <!--<origin xyz="0 0 0.026" rpy="0 0 0"/>-->
		      <origin rpy="0 0 0" xyz="0 -0.010 0.029"/>
		      <mass value="0.877"/>
		      <inertia ixx="0.01" ixy="0" ixz="0" iyy="0.01" iyz="0" izz="0.01"/>
		    </inertial>
		    <visual>
		      <origin rpy="0 0 0" xyz="0 -0.010 0.029"/>
		      <geometry>
		        <mesh filename="package://youbot_description/meshes/youbot_arm/arm4.dae"/>
		      </geometry>
		      <material name="Orange"/>
		    </visual>
		    <collision>
		      <!--<origin xyz="0 0 0.026" rpy="0 0 0" />-->
		      <origin rpy="0 0 0" xyz="0 -0.010 0.029"/>
		      <geometry>
		        <mesh filename="package://youbot_description/meshes/youbot_arm/arm4_convex.stl"/>
		        <!--<box size="0.058 0.100 0.118"/>-->
		      </geometry>
		    </collision>
		  </link>
		  <joint name="arm_joint_5" type="revolute">
		    <origin rpy="0 0 0" xyz="-0.002 0 0.130"/>
		    <parent link="arm_link_4"/>
		    <child link="arm_link_5"/>
		    <axis xyz="0 0 1"/>
		    <!--<calibration rising="${arm_5_ref}" falling="${arm_5_ref}"/>-->
		    <dynamics damping="1.0" friction="1.0"/>
		    <limit effort="10" lower="0" upper="5.84685299418" velocity="1.57079632679"/>
		    <safety_controller k_position="20" k_velocity="25" soft_lower_limit="0" soft_upper_limit="5.84585299418"/>
		  </joint>
		  <link name="arm_link_5">
		    <inertial>
		      <origin rpy="0 0 0" xyz="0.003 0 -0.034"/>
		      <mass value="0.251"/>
		      <inertia ixx="0.01" ixy="0" ixz="0" iyy="0.01" iyz="0" izz="0.01"/>
		    </inertial>
		    <visual>
		      <origin rpy="0 0 0" xyz="0.003 0 -0.034"/>
		      <geometry>
		        <mesh filename="package://youbot_description/meshes/youbot_arm/arm5.dae"/>
		      </geometry>
		      <material name="DarkGrey"/>
		    </visual>
		    <collision>
		      <origin rpy="0 0 0" xyz="0.003 0 -0.034"/>
		      <geometry>
		        <mesh filename="package://youbot_description/meshes/youbot_arm/arm5_convex.stl"/>
		        <!--<box size="0.054 0.096 0.030"/>-->
		      </geometry>
		    </collision>
		  </link>
		  <gazebo reference="arm_link_0">
		    <material value="youbot/DarkGrey"/>
		    <turnGravityOff>false</turnGravityOff>
		  </gazebo>
		  <gazebo reference="arm_link_1">
		    <!--<material value="youbot/Orange" />-->
		    <turnGravityOff>false</turnGravityOff>
		  </gazebo>
		  <gazebo reference="arm_link_2">
		    <!--<material value="youbot/Orange" />-->
		    <turnGravityOff>false</turnGravityOff>
		  </gazebo>
		  <gazebo reference="arm_link_3">
		    <!--<material value="youbot/Orange" />-->
		    <turnGravityOff>false</turnGravityOff>
		  </gazebo>
		  <gazebo reference="arm_link_4">
		    <!--<material value="youbot/Orange" />-->
		    <turnGravityOff>false</turnGravityOff>
		  </gazebo>
		  <gazebo reference="arm_link_5">
		    <!--<material value="youbot/DarkGrey" />-->
		    <turnGravityOff>false</turnGravityOff>
		  </gazebo>
		  <transmission name="arm_trans_1" type="pr2_mechanism_model/SimpleTransmission">
		    <actuator name="arm_motor_1"/>
		    <joint name="arm_joint_1"/>
		    <mechanicalReduction>1</mechanicalReduction>
		  </transmission>
		  <transmission name="arm_trans_2" type="pr2_mechanism_model/SimpleTransmission">
		    <actuator name="arm_motor_2"/>
		    <joint name="arm_joint_2"/>
		    <mechanicalReduction>1</mechanicalReduction>
		  </transmission>
		  <transmission name="arm_trans_3" type="pr2_mechanism_model/SimpleTransmission">
		    <actuator name="arm_motor_3"/>
		    <joint name="arm_joint_3"/>
		    <mechanicalReduction>1</mechanicalReduction>
		  </transmission>
		  <transmission name="arm_trans_4" type="pr2_mechanism_model/SimpleTransmission">
		    <actuator name="arm_motor_4"/>
		    <joint name="arm_joint_4"/>
		    <mechanicalReduction>1</mechanicalReduction>
		  </transmission>
		  <transmission name="arm_trans_5" type="pr2_mechanism_model/SimpleTransmission">
		    <actuator name="arm_motor_5"/>
		    <joint name="arm_joint_5"/>
		    <mechanicalReduction>1</mechanicalReduction>
		  </transmission>
		  <joint name="gripper_palm_joint" type="fixed">
		    <origin rpy="0 0 0" xyz="0 0 0"/>
		    <parent link="arm_link_5"/>
		    <child link="gripper_palm_link"/>
		  </joint>
		  <link name="gripper_palm_link">
		    <inertial>
		      <origin rpy="0 0 0" xyz="0 0 0"/>
		      <mass value="0.75"/>
		      <inertia ixx="0.01" ixy="0" ixz="0" iyy="0.01" iyz="0" izz="0.01"/>
		    </inertial>
		    <visual>
		      <origin rpy="0 0 0" xyz="0 0 0"/>
		      <geometry>
		        <mesh filename="package://youbot_description/meshes/youbot_gripper/palm.stl"/>
		      </geometry>
		      <material name="DarkGrey"/>
		    </visual>
		    <collision>
		      <origin rpy="0 0 0" xyz="0 0 0"/>
		      <geometry>
		        <!--<box size="0.050 0.094 0.054"/>-->
		        <mesh filename="package://youbot_description/meshes/youbot_gripper/palm_convex.stl"/>
		      </geometry>
		    </collision>
		  </link>
		  <joint name="gripper_finger_joint_l" type="fixed">
		    <origin rpy="0 0 3.14159265359" xyz="0.004 0.008 0.046"/>
		    <parent link="gripper_palm_link"/>
		    <child link="gripper_finger_link_l"/>
		    <axis xyz="0 -1 0"/>
		    <dynamics damping="1.0" friction="1.0"/>
		    <limit effort="1" lower="0" upper="0.0115" velocity="0.1"/>
		    <safety_controller k_position="20" k_velocity="25" soft_lower_limit="0.001" soft_upper_limit="0.011"/>
		  </joint>
		  <link name="gripper_finger_link_l">
		    <inertial>
		      <origin rpy="0 0 0" xyz="0 -0.001 0"/>
		      <mass value="0.01"/>
		      <inertia ixx="0.01" ixy="0" ixz="0" iyy="0.01" iyz="0" izz="0.01"/>
		    </inertial>
		    <visual>
		      <origin rpy="0 0 0" xyz="0 0 0"/>
		      <geometry>
		        <mesh filename="package://youbot_description/meshes/youbot_gripper/finger.stl"/>
		      </geometry>
		      <material name="DarkGrey"/>
		    </visual>
		    <collision>
		      <origin rpy="0 0 0" xyz="0 0 0"/>
		      <geometry>
		        <!--<box size="0.014 0.020 0.046"/>-->
		        <mesh filename="package://youbot_description/meshes/youbot_gripper/finger_convex.stl"/>
		      </geometry>
		    </collision>
		  </link>
		  <joint name="gripper_finger_joint_r" type="fixed">
		    <origin rpy="0 0 0" xyz="0.004 -0.008 0.046"/>
		    <parent link="gripper_palm_link"/>
		    <child link="gripper_finger_link_r"/>
		    <axis xyz="0 -1 0"/>
		    <dynamics damping="1.0" friction="1.0"/>
		    <limit effort="1" lower="0" upper="0.0115" velocity="0.1"/>
		    <safety_controller k_position="20" k_velocity="25" soft_lower_limit="0.001" soft_upper_limit="0.011"/>
		  </joint>
		  <link name="gripper_finger_link_r">
		    <inertial>
		      <origin rpy="0 0 0" xyz="0.000 -0.001 0"/>
		      <mass value="0.01"/>
		      <inertia ixx="0.01" ixy="0" ixz="0" iyy="0.01" iyz="0" izz="0.01"/>
		    </inertial>
		    <visual>
		      <origin rpy="0 0 0" xyz="0 0 0"/>
		      <geometry>
		        <mesh filename="package://youbot_description/meshes/youbot_gripper/finger.stl"/>
		      </geometry>
		      <material name="DarkGrey"/>
		    </visual>
		    <collision>
		      <origin rpy="0 0 0" xyz="0.000 0 0"/>
		      <geometry>
		        <!--<box size="0.014 0.020 0.046"/>-->
		        <mesh filename="package://youbot_description/meshes/youbot_gripper/finger_convex.stl"/>
		      </geometry>
		    </collision>
		  </link>
		  <gazebo reference="gripper_palm_link">
		    <material>Gazebo/Black</material>
		    <turnGravityOff>false</turnGravityOff>
		    <selfCollide>true</selfCollide>
		  </gazebo>
		  <gazebo reference="gripper_finger_l_link">
		    <material>Gazebo/Black</material>
		    <turnGravityOff>false</turnGravityOff>
		    <selfCollide>true</selfCollide>
		  </gazebo>
		  <gazebo reference="gripper_finger_r_link">
		    <material>Gazebo/Black</material>
		    <turnGravityOff>false</turnGravityOff>
		    <selfCollide>true</selfCollide>
		  </gazebo>
		  <transmission name="gripper_finger_l_trans" type="pr2_mechanism_model/SimpleTransmission">
		    <actuator name="gripper_finger_l_motor"/>
		    <joint name="gripper_finger_joint_l"/>
		    <mechanicalReduction>1</mechanicalReduction>
		  </transmission>
		  <transmission name="gripper_finger_r_trans" type="pr2_mechanism_model/SimpleTransmission">
		    <actuator name="gripper_finger_r_motor"/>
		    <joint name="gripper_finger_joint_r"/>
		    <mechanicalReduction>1</mechanicalReduction>
		  </transmission>
		</robot>
		
		[0m[31m // URDF xml model[0m
   [37minclude_base[0m (bool) = [33mfalse[0m[31m // if true, include base in inverse dynamics[0m
   [37mforce_gain[0m (float64[]) = [33m{}[0m[31m // base wrench to twist gain [az, x, y][0m
[35moperations[0m:
[37mJointState[0m (/sensor_msgs/JointState)  = 
		[32mheader:   {frame_id="",stamp="1.33614e+09",seq=0}
		names:    {"arm_joint_1","arm_joint_2","arm_joint_3","arm_joint_4","arm_joint_5"}
		position: {-0.0010324870687692,0.00025566346464761,-0.0018100973297051,0.0082316433828793,0.0025710382219492}
		velocity: {0,0,0,0,0}
		effort:   {0.031356,0.250848,0.0402,0,0.031311}
		[0m
[37mEEWrench[0m (/geometry_msgs/Wrench)  =  NoData
[37mJointAccelerations[0m (/motion_control_msgs/JointAccelerations)  =  NoData
[37mJointEfforts[0m (/motion_control_msgs/JointEfforts)  = [36m{efforts={0,0,0,0,0},names={}}[0m
[37mBaseTwist[0m (/geometry_msgs/Twist)  = [36m{linear={y=0,x=0,z=0},angular={y=0,x=0,z=0}}[0m

> 0 F [[    0.999999,  0.00103249,           0;
  -0.00103249,    0.999999,           0;
            0,           0,           1]
[       0.024,           0,       0.096]]
0 Velocity of link[           0,           0,           0,           0,           0,           0]
0 Acceleration of link[           0,           0,        9.81,           0,           0,           0]
0 S[i][           0,           0,           0,           0,           0,           1]
0 Force at link[           0,           0,     23.6617,           0,           0,           0]
1 F [[           1,           0,-0.000255663;
            0,           1,           0;
  0.000255663,           0,           1]
[       0.033,           0,       0.019]]
1 Velocity of link[           0,           0,           0,           0,           0,           0]
1 Acceleration of link[  0.00250806,           0,        9.81,           0,           0,           0]
1 S[i][           0,           0,           0,           0,          -1,           0]
1 Force at link[  0.00289681,           0,     11.3305,   -0.362578, 0.000225951, 9.26978e-05]
2 F [[    0.999998,           0,  -0.0018101;
            0,           1,           0;
    0.0018101,           0,    0.999998]
[           0,           0,       0.155]]
2 Velocity of link[           0,           0,           0,           0,           0,           0]
2 Acceleration of link[   0.0202651,           0,     9.80998,           0,           0,           0]
2 S[i][           0,           0,           0,           0,           1,           0]
2 Force at link[   0.0189276,           0,     9.16252,    0.256551,  0.00149528,-0.000529973]
3 F [[    0.999966,           0, -0.00823155;
            0,           1,           0;
   0.00823155,           0,    0.999966]
[           0,           0,       0.135]]
3 Velocity of link[           0,           0,           0,           0,           0,           0]
3 Acceleration of link[    0.101016,           0,     9.80948,           0,           0,           0]
3 S[i][           0,           0,           0,           0,          -1,           0]
3 Force at link[   0.0885908,           0,     8.60291,  -0.0860291,  0.00256913, 0.000885908]
4 F [[    0.999997, -0.00257104,           0;
   0.00257104,    0.999997,           0;
            0,           0,           1]
[      -0.002,           0,        0.13]]
4 Velocity of link[           0,           0,           0,           0,           0,           0]
4 Acceleration of link[    0.101015,-0.000259715,     9.80948,           0,           0,           0]
4 S[i][           0,           0,           0,           0,           0,           1]
4 Force at link[   0.0253549,-6.51885e-05,     2.46218,-2.21641e-06,  -0.0082486,-1.95565e-07]
4 Force in force rec[   0.0253549,-6.51885e-05,     2.46218,-2.21641e-06,  -0.0082486,-1.95565e-07]
3 Force in force rec[    0.113946, 7.43139e-21,     11.0651,  -0.0860101,  0.00254105, 0.000885713]
2 Force in force rec[   0.0417866, 7.43139e-21,     20.2282,    0.170536,   0.0071223,-0.000352287]
1 Force in force rec[  0.00806842, 7.43139e-21,     31.5588,   -0.192041,  0.00814986, 4.90979e-05]
0 Force in force rec[ 1.60852e-17, 7.43139e-21,     55.2205,   -0.192041,    -1.03329, 2.51368e-20]

In update hook after cartjnt jacc      0.000000   0.000000   0.000000   0.000000   0.000000
In update hook after cartjnt jtorques   0.000000   -0.008150   0.007122   -0.002541   -0.000000
0 F [[    0.999999,  0.00103249,           0;
  -0.00103249,    0.999999,           0;
            0,           0,           1]
[       0.024,           0,       0.096]]
0 Velocity of link[           0,           0,           0,           0,           0,           0]
0 Acceleration of link[           0,           0,        9.81,           0,           0,           0]
0 S[i][           0,           0,           0,           0,           0,           1]
0 Force at link[           0,           0,     23.6617,           0,           0,           0]
1 F [[           1,           0,-0.000255663;
            0,           1,           0;
  0.000255663,           0,           1]
[       0.033,           0,       0.019]]
1 Velocity of link[           0,           0,           0,           0,           0,           0]
1 Acceleration of link[  0.00250806,           0,        9.81,           0,           0,           0]
1 S[i][           0,           0,           0,           0,          -1,           0]
1 Force at link[  0.00289681,           0,     11.3305,   -0.362578, 0.000225951, 9.26978e-05]
2 F [[    0.999998,           0,  -0.0018101;
            0,           1,           0;
    0.0018101,           0,    0.999998]
[           0,           0,       0.155]]
2 Velocity of link[           0,           0,           0,           0,           0,           0]
2 Acceleration of link[   0.0202651,           0,     9.80998,           0,           0,           0]
2 S[i][           0,           0,           0,           0,           1,           0]
2 Force at link[   0.0189276,           0,     9.16252,    0.256551,  0.00149528,-0.000529973]
3 F [[    0.999966,           0, -0.00823155;
            0,           1,           0;
   0.00823155,           0,    0.999966]
[           0,           0,       0.135]]
3 Velocity of link[           0,           0,           0,           0,           0,           0]
3 Acceleration of link[    0.101016,           0,     9.80948,           0,           0,           0]
3 S[i][           0,           0,           0,           0,          -1,           0]
3 Force at link[   0.0885908,           0,     8.60291,  -0.0860291,  0.00256913, 0.000885908]
4 F [[    0.999997, -0.00257104,           0;
   0.00257104,    0.999997,           0;
            0,           0,           1]
[      -0.002,           0,        0.13]]
4 Velocity of link[           0,           0,           0,           0,           0,           0]
4 Acceleration of link[    0.101015,-0.000259715,     9.80948,           0,           0,           0]
4 S[i][           0,           0,           0,           0,           0,           1]
4 Force at link[   0.0253549,-6.51885e-05,     2.46218,-2.21641e-06,  -0.0082486,-1.95565e-07]
4 Force in force rec[   0.0253549,-6.51885e-05,     2.46218,-2.21641e-06,  -0.0082486,-1.95565e-07]
3 Force in force rec[    0.113946, 7.43139e-21,     11.0651,  -0.0860101,  0.00254105, 0.000885713]
2 Force in force rec[   0.0417866, 7.43139e-21,     20.2282,    0.170536,   0.0071223,-0.000352287]
1 Force in force rec[  0.00806842, 7.43139e-21,     31.5588,   -0.192041,  0.00814986, 4.90979e-05]
0 Force in force rec[ 1.60852e-17, 7.43139e-21,     55.2205,   -0.192041,    -1.03329, 2.51368e-20]

In update hook after cartjnt jacc      0.000000   0.000000   0.000000   0.000000   0.000000
In update hook after cartjnt jtorques   0.000000   -0.008150   0.007122   -0.002541   -0.000000
0 F [[    0.999999,  0.00103249,           0;
  -0.00103249,    0.999999,           0;
            0,           0,           1]
[       0.024,           0,       0.096]]
0 Velocity of link[           0,           0,           0,           0,           0,           0]
0 Acceleration of link[           0,           0,        9.81,           0,           0,           0]
0 S[i][           0,           0,           0,           0,           0,           1]
0 Force at link[           0,           0,     23.6617,           0,           0,           0]
1 F [[           1,           0,-0.000255663;
            0,           1,           0;
  0.000255663,           0,           1]
[       0.033,           0,       0.019]]
1 Velocity of link[           0,           0,           0,           0,           0,           0]
1 Acceleration of link[  0.00250806,           0,        9.81,           0,           0,           0]
1 S[i][           0,           0,           0,           0,          -1,           0]
1 Force at link[  0.00289681,           0,     11.3305,   -0.362578, 0.000225951, 9.26978e-05]
2 F [[    0.999998,           0,  -0.0018101;
            0,           1,           0;
    0.0018101,           0,    0.999998]
[           0,           0,       0.155]]
2 Velocity of link[           0,           0,           0,           0,           0,           0]
2 Acceleration of link[   0.0202651,           0,     9.80998,           0,           0,           0]
2 S[i][           0,           0,           0,           0,           1,           0]
2 Force at link[   0.0189276,           0,     9.16252,    0.256551,  0.00149528,-0.000529973]
3 F [[    0.999966,           0, -0.00823155;
            0,           1,           0;
   0.00823155,           0,    0.999966]
[           0,           0,       0.135]]
3 Velocity of link[           0,           0,           0,           0,           0,           0]
3 Acceleration of link[    0.101016,           0,     9.80948,           0,           0,           0]
3 S[i][           0,           0,           0,           0,          -1,           0]
3 Force at link[   0.0885908,           0,     8.60291,  -0.0860291,  0.00256913, 0.000885908]
4 F [[    0.999997, -0.00257104,           0;
   0.00257104,    0.999997,           0;
            0,           0,           1]
[      -0.002,           0,        0.13]]
4 Velocity of link[           0,           0,           0,           0,           0,           0]
4 Acceleration of link[    0.101015,-0.000259715,     9.80948,           0,           0,           0]
4 S[i][           0,           0,           0,           0,           0,           1]
4 Force at link[   0.0253549,-6.51885e-05,     2.46218,-2.21641e-06,  -0.0082486,-1.95565e-07]
4 Force in force rec[   0.0253549,-6.51885e-05,     2.46218,-2.21641e-06,  -0.0082486,-1.95565e-07]
3 Force in force rec[    0.113946, 7.43139e-21,     11.0651,  -0.0860101,  0.00254105, 0.000885713]
2 Force in force rec[   0.0417866, 7.43139e-21,     20.2282,    0.170536,   0.0071223,-0.000352287]
1 Force in force rec[  0.00806842, 7.43139e-21,     31.5588,   -0.192041,  0.00814986, 4.90979e-05]
0 Force in force rec[ 1.60852e-17, 7.43139e-21,     55.2205,   -0.192041,    -1.03329, 2.51368e-20]

In update hook after cartjnt jacc      0.000000   0.000000   0.000000   0.000000   0.000000
In update hook after cartjnt jtorques   0.000000   -0.008150   0.007122   -0.002541   -0.000000
^C... logging to /home/youbot/.ros/log/9a0a5fce-95fa-11e1-99d1-000bab30257b/roslaunch-youbot-pc-13153.log
Checking log directory for disk usage. This may take awhile.
Press Ctrl-C to interrupt
Done checking log file disk usage. Usage is <1GB.
]2;launch/youbot_dynamic_controller.launch
[1mstarted roslaunch server http://youbot-pc:46819/[0m

SUMMARY
========

PARAMETERS
 * /rosversion
 * /rosdistro
 * /robot_description

NODES
  /
    rob_st_pub (robot_state_publisher/state_publisher)
    YoubotMaster (ocl/rttlua-gnulinux)

auto-starting new master
[1mprocess[master]: started with pid [13171][0m
[1mROS_MASTER_URI=http://localhost:11311[0m
]2;launch/youbot_dynamic_controller.launch http://localhost:11311
[1msetting /run_id to 9a0a5fce-95fa-11e1-99d1-000bab30257b[0m
[1mprocess[rosout-1]: started with pid [13185][0m
started core service [/rosout]
[1mprocess[rob_st_pub-2]: started with pid [13196][0m
[1mprocess[YoubotMaster-3]: started with pid [13198][0m
[YoubotMaster-3] killing on exit
[rob_st_pub-2] killing on exit
[rosout-1] killing on exit
[master] killing on exit
shutting down processing monitor...
... shutting down processing monitor complete
[1mdone[0m
